<?xml version="1.0" ?>
<robot name="converted_robot">
   <link name="world">
      <inertial>
         <origin xyz="0.0 0.0 0.0" rpy="0.0 0.0 0.0"/>
         <mass value="0.0"/>
         <inertia ixx="0.0" iyy="0.0" izz="0.0" ixy="0" ixz="0" iyz="0"/>
      </inertial>
      <visual name="base">
         <origin xyz="-0.001988568020268065 0.00011251475491376964 0.06484099137569184" rpy="0.04439421331694594 0.00023003077050942622 1.5061911797633354"/>
         <geometry>
            <mesh filename="converted_base.stl"/>
         </geometry>
         <material name="white"/>
      </visual>
   </link>
   <link name="link1">
      <inertial>
         <origin xyz="0.00022 0.02951 -0.0124" rpy="0.4355485641645795 -0.01151975215954959 0.03408854412398267"/>
         <mass value="2.3814"/>
         <inertia ixx="0.00585677" iyy="0.00544457" izz="0.00312311" ixy="0" ixz="0" iyz="0"/>
      </inertial>
      <visual name="link1">
         <origin xyz="-0.00013218954812539433 0.007464197279856433 -0.02711553977556827" rpy="-0.33362300930831684 0.0034678881741270207 -0.002737431020260937"/>
         <geometry>
            <mesh filename="converted_link1.stl"/>
         </geometry>
         <material name="white"/>
      </visual>
   </link>
   <link name="joint1">
      <inertial>
         <origin xyz="0.0 0.0 0.0" rpy="0.0 0.0 0.0"/>
         <mass value="0.001"/>
         <inertia ixx="1e-09" iyy="1e-09" izz="1e-09" ixy="0" ixz="0" iyz="0"/>
      </inertial>
   </link>
   <joint type="revolute" name="joint1">
      <parent link="world"/>
      <child link="joint1"/>
      <origin xyz="0.0 0.0 0.267" rpy="0.0 0.0 0.0"/>
      <axis xyz="0.0 0.0 1.0"/>
      <limit lower="-3.11018" upper="3.11018" effort="100" velocity="100"/>
   </joint>
   <joint type="fixed" name="joint1_offset">
      <parent link="joint1"/>
      <child link="link1"/>
      <origin xyz="-0.0 -0.0 -0.0" rpy="0.0 0.0 0.0"/>
   </joint>
   <link name="link2">
      <inertial>
         <origin xyz="0.03881 -0.22783 0.03496" rpy="1.348973079365043 0.589472079798409 -0.32201355688466154"/>
         <mass value="2.2675"/>
         <inertia ixx="0.0304531" iyy="0.0270745" izz="0.0039329" ixy="0" ixz="0" iyz="0"/>
      </inertial>
      <visual name="link2">
         <origin xyz="0.014875566187991445 -0.16194855468132002 0.02964404368210932" rpy="1.9174384122134032 0.3390205710115355 0.2968760087267535"/>
         <geometry>
            <mesh filename="converted_link2.stl"/>
         </geometry>
         <material name="white"/>
      </visual>
   </link>
   <link name="joint2">
      <inertial>
         <origin xyz="0.0 0.0 0.0" rpy="0.0 0.0 0.0"/>
         <mass value="0.001"/>
         <inertia ixx="1e-09" iyy="1e-09" izz="1e-09" ixy="0" ixz="0" iyz="0"/>
      </inertial>
   </link>
   <joint type="revolute" name="joint2">
      <parent link="link1"/>
      <child link="joint2"/>
      <origin xyz="0.0 0.0 0.0" rpy="-1.5708005694372709 0.0 0.0"/>
      <axis xyz="0.0 0.0 1.0"/>
      <limit lower="-2.059" upper="2.0944" effort="100" velocity="100"/>
   </joint>
   <joint type="fixed" name="joint2_offset">
      <parent link="joint2"/>
      <child link="link2"/>
      <origin xyz="-0.0 -0.0 -0.0" rpy="0.0 0.0 0.0"/>
   </joint>
   <link name="link3">
      <inertial>
         <origin xyz="0.07041 0.11631 0.0107" rpy="-2.107790652059732 -0.6582306530693534 -2.515252296079175"/>
         <mass value="1.875"/>
         <inertia ixx="0.00536785" iyy="0.00536785" izz="0.00536785" ixy="0" ixz="0" iyz="0"/>
      </inertial>
      <visual name="link3">
         <origin xyz="0.05915374366666802 0.07651418456626077 0.04021116008138051" rpy="0.9997568989372841 0.1766060258401485 -0.6619722856298305"/>
         <geometry>
            <mesh filename="converted_link3.stl"/>
         </geometry>
         <material name="white"/>
      </visual>
   </link>
   <link name="joint3">
      <inertial>
         <origin xyz="0.0 0.0 0.0" rpy="0.0 0.0 0.0"/>
         <mass value="0.001"/>
         <inertia ixx="1e-09" iyy="1e-09" izz="1e-09" ixy="0" ixz="0" iyz="0"/>
      </inertial>
   </link>
   <joint type="revolute" name="joint3">
      <parent link="link2"/>
      <child link="joint3"/>
      <origin xyz="0.0535 -0.2845 0.0" rpy="0.0 0.0 0.0"/>
      <axis xyz="0.0 0.0 1.0"/>
      <limit lower="-3.11018" upper="0.19198" effort="100" velocity="100"/>
   </joint>
   <joint type="fixed" name="joint3_offset">
      <parent link="joint3"/>
      <child link="link3"/>
      <origin xyz="-0.0 -0.0 -0.0" rpy="0.0 0.0 0.0"/>
   </joint>
   <link name="link4">
      <inertial>
         <origin xyz="-0.00018 0.01798 -0.02291" rpy="0.07382928357874731 -0.005198268016330498 0.01850720867997557"/>
         <mass value="1.3192"/>
         <inertia ixx="0.0048962" iyy="0.00447396" izz="0.0013261" ixy="0" ixz="0" iyz="0"/>
      </inertial>
      <visual name="link4">
         <origin xyz="-0.0001933115420370148 0.031599603176915084 -0.07229682669267906" rpy="-0.2899363380198844 0.004123601154868206 0.015988586424917947"/>
         <geometry>
            <mesh filename="converted_link4.stl"/>
         </geometry>
         <material name="white"/>
      </visual>
   </link>
   <link name="joint4">
      <inertial>
         <origin xyz="0.0 0.0 0.0" rpy="0.0 0.0 0.0"/>
         <mass value="0.001"/>
         <inertia ixx="1e-09" iyy="1e-09" izz="1e-09" ixy="0" ixz="0" iyz="0"/>
      </inertial>
   </link>
   <joint type="revolute" name="joint4">
      <parent link="link3"/>
      <child link="joint4"/>
      <origin xyz="0.0775 0.3425 0.0" rpy="-1.5708005694372709 0.0 0.0"/>
      <axis xyz="0.0 0.0 1.0"/>
      <limit lower="-3.11018" upper="3.11018" effort="100" velocity="100"/>
   </joint>
   <joint type="fixed" name="joint4_offset">
      <parent link="joint4"/>
      <child link="link4"/>
      <origin xyz="-0.0 -0.0 -0.0" rpy="0.0 0.0 0.0"/>
   </joint>
   <link name="link5">
      <inertial>
         <origin xyz="0.0651 0.03096 0.00315" rpy="-1.3129473580943467 -0.9673430130256786 -2.33246926539584"/>
         <mass value="1.33854"/>
         <inertia ixx="0.00253403" iyy="0.00196507" izz="0.00114012" ixy="0" ixz="0" iyz="0"/>
      </inertial>
      <visual name="link5">
         <origin xyz="0.048892960928717207 0.011180520389591274 0.009056193467818132" rpy="-2.9389689832315877 -1.280443051852528 0.09467892860533325"/>
         <geometry>
            <mesh filename="converted_link5.stl"/>
         </geometry>
         <material name="white"/>
      </visual>
   </link>
   <link name="joint5">
      <inertial>
         <origin xyz="0.0 0.0 0.0" rpy="0.0 0.0 0.0"/>
         <mass value="0.001"/>
         <inertia ixx="1e-09" iyy="1e-09" izz="1e-09" ixy="0" ixz="0" iyz="0"/>
      </inertial>
   </link>
   <joint type="revolute" name="joint5">
      <parent link="link4"/>
      <child link="joint5"/>
      <origin xyz="0.0 0.0 0.0" rpy="1.5708005694372709 0.0 0.0"/>
      <axis xyz="0.0 0.0 1.0"/>
      <limit lower="-1.69297" upper="3.11018" effort="100" velocity="100"/>
   </joint>
   <joint type="fixed" name="joint5_offset">
      <parent link="joint5"/>
      <child link="link5"/>
      <origin xyz="-0.0 -0.0 -0.0" rpy="0.0 0.0 0.0"/>
   </joint>
   <link name="link6">
      <inertial>
         <origin xyz="0.0046396 -0.00165489 0.0681261" rpy="0.020458185813497568 0.026800705860281715 1.5773080767471808"/>
         <mass value="1.38018"/>
         <inertia ixx="0.00334838" iyy="0.00302786" izz="0.0011071" ixy="0" ixz="0" iyz="0"/>
      </inertial>
      <visual name="end_tool">
         <origin xyz="3.4268701643423586e-08 -0.001435304389793365 -0.013516014948721122" rpy="-3.1415761422693795 -1.5687955686077422 -1.5707963267948966"/>
         <geometry>
            <mesh filename="converted_end_tool.stl"/>
         </geometry>
         <material name="white"/>
      </visual>
      <visual name="ft_sensor_scaled">
         <origin xyz="-0.0025413173168710784 0.0012844602929361069 0.02934122839286124" rpy="-3.106501645314344 -1.3615361730076154 2.57565154603999"/>
         <geometry>
            <mesh filename="converted_ft_sensor_scaled.stl"/>
         </geometry>
         <material name="white"/>
      </visual>
      <visual name="d435_with_cam_stand">
         <origin xyz="0.05319046898036692 -0.0010342940638096278 0.072628412908257" rpy="-0.03274316095589082 -1.381627305955616 3.139114546177682"/>
         <geometry>
            <mesh filename="converted_d435_with_cam_stand.stl"/>
         </geometry>
         <material name="white"/>
      </visual>
      <visual name="base_link">
         <origin xyz="-0.0013675233777249022 0.00018071029397544007 0.10590832027619651" rpy="0.03567861154889 -0.06311112110604888 -0.00044563792998500315"/>
         <geometry>
            <mesh filename="converted_base_link.stl"/>
         </geometry>
         <material name="white"/>
      </visual>
   </link>
   <link name="joint6">
      <inertial>
         <origin xyz="0.0 0.0 0.0" rpy="0.0 0.0 0.0"/>
         <mass value="0.001"/>
         <inertia ixx="1e-09" iyy="1e-09" izz="1e-09" ixy="0" ixz="0" iyz="0"/>
      </inertial>
   </link>
   <joint type="revolute" name="joint6">
      <parent link="link5"/>
      <child link="joint6"/>
      <origin xyz="0.076 0.097 0.0" rpy="-1.5708005694372709 0.0 0.0"/>
      <axis xyz="0.0 0.0 1.0"/>
      <limit lower="-3.11018" upper="3.11018" effort="100" velocity="100"/>
   </joint>
   <joint type="fixed" name="joint6_offset">
      <parent link="joint6"/>
      <child link="link6"/>
      <origin xyz="-0.0 -0.0 -0.0" rpy="0.0 0.0 0.0"/>
   </joint>
   <link name="link_eef">
      <inertial>
         <origin xyz="0.0 0.0 0.0" rpy="0.0 0.0 0.0"/>
         <mass value="0.0"/>
         <inertia ixx="0.0" iyy="0.0" izz="0.0" ixy="0" ixz="0" iyz="0"/>
      </inertial>
   </link>
   <link name="link62link_eef_fixed">
      <inertial>
         <origin xyz="0.0 0.0 0.0" rpy="0.0 0.0 0.0"/>
         <mass value="0.001"/>
         <inertia ixx="1e-09" iyy="1e-09" izz="1e-09" ixy="0" ixz="0" iyz="0"/>
      </inertial>
   </link>
   <joint type="fixed" name="link62link_eef_fixed">
      <parent link="link6"/>
      <child link="link62link_eef_fixed"/>
      <origin xyz="0.0 0.0 0.0" rpy="0.0 0.0 0.0"/>
   </joint>
   <joint type="fixed" name="link62link_eef_fixed_offset">
      <parent link="link62link_eef_fixed"/>
      <child link="link_eef"/>
      <origin xyz="-0.0 -0.0 -0.0" rpy="0.0 0.0 0.0"/>
   </joint>
   <link name="link_tcp">
      <inertial>
         <origin xyz="0.0 0.0 0.0" rpy="0.0 0.0 0.0"/>
         <mass value="0.0"/>
         <inertia ixx="0.0" iyy="0.0" izz="0.0" ixy="0" ixz="0" iyz="0"/>
      </inertial>
   </link>
   <link name="link_eef2link_tcp_fixed">
      <inertial>
         <origin xyz="0.0 0.0 0.0" rpy="0.0 0.0 0.0"/>
         <mass value="0.001"/>
         <inertia ixx="1e-09" iyy="1e-09" izz="1e-09" ixy="0" ixz="0" iyz="0"/>
      </inertial>
   </link>
   <joint type="fixed" name="link_eef2link_tcp_fixed">
      <parent link="link_eef"/>
      <child link="link_eef2link_tcp_fixed"/>
      <origin xyz="0.0 0.0 0.2" rpy="-1.5699435554720513 -1.5664889788184846 -1.5716491060286246"/>
   </joint>
   <joint type="fixed" name="link_eef2link_tcp_fixed_offset">
      <parent link="link_eef2link_tcp_fixed"/>
      <child link="link_tcp"/>
      <origin xyz="-0.0 -0.0 -0.0" rpy="0.0 0.0 0.0"/>
   </joint>
   <link name="left_outer_knuckle">
      <inertial>
         <origin xyz="0.0 0.021559 0.015181" rpy="2.145090756651822 0.0 0.0"/>
         <mass value="0.033618"/>
         <inertia ixx="1.9111e-05" iyy="1.79089e-05" izz="1.90167e-06" ixy="0" ixz="0" iyz="0"/>
      </inertial>
      <visual name="left_outer_knuckle">
         <origin xyz="2.459128747530784e-11 0.01732745566852309 0.015107389964830558" rpy="2.135531627703855 0.0 0.0"/>
         <geometry>
            <mesh filename="converted_left_outer_knuckle.stl"/>
         </geometry>
         <material name="white"/>
      </visual>
   </link>
   <link name="drive_joint">
      <inertial>
         <origin xyz="0.0 0.0 0.0" rpy="0.0 0.0 0.0"/>
         <mass value="0.001"/>
         <inertia ixx="1e-09" iyy="1e-09" izz="1e-09" ixy="0" ixz="0" iyz="0"/>
      </inertial>
   </link>
   <joint type="revolute" name="drive_joint">
      <parent link="link_eef"/>
      <child link="drive_joint"/>
      <origin xyz="0.0 0.035 0.119098" rpy="0.0 0.0 0.0"/>
      <axis xyz="1.0 0.0 0.0"/>
      <limit lower="0.0" upper="0.85" effort="100" velocity="100"/>
   </joint>
   <joint type="fixed" name="drive_joint_offset">
      <parent link="drive_joint"/>
      <child link="left_outer_knuckle"/>
      <origin xyz="-0.0 -0.0 -0.0" rpy="0.0 0.0 0.0"/>
   </joint>
   <link name="left_finger">
      <inertial>
         <origin xyz="0.0 -0.016413 0.029258" rpy="0.0 -0.32773246497472885 1.5707963267948966"/>
         <mass value="0.048304"/>
         <inertia ixx="1.88037e-05" iyy="1.7493e-05" izz="3.56792e-06" ixy="0" ixz="0" iyz="0"/>
      </inertial>
      <visual name="left_finger">
         <origin xyz="1.4807619616801453e-05 -0.015549807258493559 0.028040098559196317" rpy="-0.001912485275442726 -0.365143411739667 1.5726924743770283"/>
         <geometry>
            <mesh filename="converted_left_finger.stl"/>
         </geometry>
         <material name="white"/>
      </visual>
   </link>
   <link name="left_finger_joint">
      <inertial>
         <origin xyz="0.0 0.0 0.0" rpy="0.0 0.0 0.0"/>
         <mass value="0.001"/>
         <inertia ixx="1e-09" iyy="1e-09" izz="1e-09" ixy="0" ixz="0" iyz="0"/>
      </inertial>
   </link>
   <joint type="revolute" name="left_finger_joint">
      <parent link="left_outer_knuckle"/>
      <child link="left_finger_joint"/>
      <origin xyz="0.0 0.035465 0.042039" rpy="0.0 0.0 0.0"/>
      <axis xyz="-1.0 0.0 0.0"/>
      <limit lower="0.0" upper="0.85" effort="100" velocity="100"/>
   </joint>
   <joint type="fixed" name="left_finger_joint_offset">
      <parent link="left_finger_joint"/>
      <child link="left_finger"/>
      <origin xyz="-0.0 -0.0 -0.0" rpy="0.0 0.0 0.0"/>
   </joint>
   <link name="left_inner_knuckle">
      <inertial>
         <origin xyz="1.86601e-06 0.0220468 0.0261335" rpy="-2.8572677202568355e-05 0.7007746676036897 1.5707964243166743"/>
         <mass value="0.0230126"/>
         <inertia ixx="8.34216e-06" iyy="6.0949e-06" izz="2.75601e-06" ixy="0" ixz="0" iyz="0"/>
      </inertial>
      <visual name="left_inner_knuckle">
         <origin xyz="2.8477847106074318e-05 0.020923749754326485 0.02480264390787294" rpy="0.002795912857278782 0.7007662187921664 1.5706785731507964"/>
         <geometry>
            <mesh filename="converted_left_inner_knuckle.stl"/>
         </geometry>
         <material name="white"/>
      </visual>
   </link>
   <link name="left_inner_knuckle_joint">
      <inertial>
         <origin xyz="0.0 0.0 0.0" rpy="0.0 0.0 0.0"/>
         <mass value="0.001"/>
         <inertia ixx="1e-09" iyy="1e-09" izz="1e-09" ixy="0" ixz="0" iyz="0"/>
      </inertial>
   </link>
   <joint type="revolute" name="left_inner_knuckle_joint">
      <parent link="link_eef"/>
      <child link="left_inner_knuckle_joint"/>
      <origin xyz="0.0 0.02 0.134098" rpy="0.0 0.0 0.0"/>
      <axis xyz="1.0 0.0 0.0"/>
      <limit lower="0.0" upper="0.85" effort="100" velocity="100"/>
   </joint>
   <joint type="fixed" name="left_inner_knuckle_joint_offset">
      <parent link="left_inner_knuckle_joint"/>
      <child link="left_inner_knuckle"/>
      <origin xyz="-0.0 -0.0 -0.0" rpy="0.0 0.0 0.0"/>
   </joint>
   <link name="right_outer_knuckle">
      <inertial>
         <origin xyz="0.0 -0.021559 0.015181" rpy="0.9965018969379716 0.0 0.0"/>
         <mass value="0.033618"/>
         <inertia ixx="1.9111e-05" iyy="1.79089e-05" izz="1.90167e-06" ixy="0" ixz="0" iyz="0"/>
      </inertial>
      <visual name="right_outer_knuckle">
         <origin xyz="-2.459128747530784e-11 -0.01732745566852309 0.015107389964830558" rpy="1.0060610258859382 0.0 0.0"/>
         <geometry>
            <mesh filename="converted_right_outer_knuckle.stl"/>
         </geometry>
         <material name="white"/>
      </visual>
   </link>
   <link name="right_outer_knuckle_joint">
      <inertial>
         <origin xyz="0.0 0.0 0.0" rpy="0.0 0.0 0.0"/>
         <mass value="0.001"/>
         <inertia ixx="1e-09" iyy="1e-09" izz="1e-09" ixy="0" ixz="0" iyz="0"/>
      </inertial>
   </link>
   <joint type="revolute" name="right_outer_knuckle_joint">
      <parent link="link_eef"/>
      <child link="right_outer_knuckle_joint"/>
      <origin xyz="0.0 -0.035 0.119098" rpy="0.0 0.0 0.0"/>
      <axis xyz="-1.0 0.0 0.0"/>
      <limit lower="0.0" upper="0.85" effort="100" velocity="100"/>
   </joint>
   <joint type="fixed" name="right_outer_knuckle_joint_offset">
      <parent link="right_outer_knuckle_joint"/>
      <child link="right_outer_knuckle"/>
      <origin xyz="-0.0 -0.0 -0.0" rpy="0.0 0.0 0.0"/>
   </joint>
   <link name="right_finger">
      <inertial>
         <origin xyz="0.0 0.016413 0.029258" rpy="0.0 0.32774083658509623 1.5707963267948966"/>
         <mass value="0.048304"/>
         <inertia ixx="1.88038e-05" iyy="1.7493e-05" izz="3.56779e-06" ixy="0" ixz="0" iyz="0"/>
      </inertial>
      <visual name="right_finger">
         <origin xyz="2.8375271036235104e-05 0.015532154030621503 0.028008582622386046" rpy="-0.0036607875176824455 0.3654430266742408 1.5671143312790885"/>
         <geometry>
            <mesh filename="converted_right_finger.stl"/>
         </geometry>
         <material name="white"/>
      </visual>
   </link>
   <link name="right_finger_joint">
      <inertial>
         <origin xyz="0.0 0.0 0.0" rpy="0.0 0.0 0.0"/>
         <mass value="0.001"/>
         <inertia ixx="1e-09" iyy="1e-09" izz="1e-09" ixy="0" ixz="0" iyz="0"/>
      </inertial>
   </link>
   <joint type="revolute" name="right_finger_joint">
      <parent link="right_outer_knuckle"/>
      <child link="right_finger_joint"/>
      <origin xyz="0.0 -0.035465 0.042039" rpy="0.0 0.0 0.0"/>
      <axis xyz="1.0 0.0 0.0"/>
      <limit lower="0.0" upper="0.85" effort="100" velocity="100"/>
   </joint>
   <joint type="fixed" name="right_finger_joint_offset">
      <parent link="right_finger_joint"/>
      <child link="right_finger"/>
      <origin xyz="-0.0 -0.0 -0.0" rpy="0.0 0.0 0.0"/>
   </joint>
   <link name="right_inner_knuckle">
      <inertial>
         <origin xyz="1.866e-06 -0.022047 0.026133" rpy="-2.920732354600332e-05 -0.7007410762952847 1.5707979664218301"/>
         <mass value="0.023013"/>
         <inertia ixx="8.34209e-06" iyy="6.0949e-06" izz="2.75601e-06" ixy="0" ixz="0" iyz="0"/>
      </inertial>
      <visual name="right_inner_knuckle">
         <origin xyz="-3.4343823358275674e-06 -0.02092196405530607 0.024800978324764668" rpy="-0.0003842496110303283 -0.700727986800333 1.5708075585716363"/>
         <geometry>
            <mesh filename="converted_right_inner_knuckle.stl"/>
         </geometry>
         <material name="white"/>
      </visual>
   </link>
   <link name="right_inner_knuckle_joint">
      <inertial>
         <origin xyz="0.0 0.0 0.0" rpy="0.0 0.0 0.0"/>
         <mass value="0.001"/>
         <inertia ixx="1e-09" iyy="1e-09" izz="1e-09" ixy="0" ixz="0" iyz="0"/>
      </inertial>
   </link>
   <joint type="revolute" name="right_inner_knuckle_joint">
      <parent link="link_eef"/>
      <child link="right_inner_knuckle_joint"/>
      <origin xyz="0.0 -0.02 0.134098" rpy="0.0 0.0 0.0"/>
      <axis xyz="-1.0 0.0 0.0"/>
      <limit lower="0.0" upper="0.85" effort="100" velocity="100"/>
   </joint>
   <joint type="fixed" name="right_inner_knuckle_joint_offset">
      <parent link="right_inner_knuckle_joint"/>
      <child link="right_inner_knuckle"/>
      <origin xyz="-0.0 -0.0 -0.0" rpy="0.0 0.0 0.0"/>
   </joint>
   <link name="spoon">
      <inertial>
         <origin xyz="0.11445137782354108 -0.00013732493883597768 -0.00013556152663841278" rpy="1.5708002471881757 3.036328703798219e-06 1.5473716817218728"/>
         <mass value="0.025"/>
         <inertia ixx="2.8617567605405535e-05" iyy="2.7902487045757164e-05" izz="1.2129332458179779e-06" ixy="0" ixz="0" iyz="0"/>
      </inertial>
   </link>
   <link name="link_eef2spoon_fixed">
      <inertial>
         <origin xyz="0.0 0.0 0.0" rpy="0.0 0.0 0.0"/>
         <mass value="0.001"/>
         <inertia ixx="1e-09" iyy="1e-09" izz="1e-09" ixy="0" ixz="0" iyz="0"/>
      </inertial>
   </link>
   <joint type="fixed" name="link_eef2spoon_fixed">
      <parent link="link_eef"/>
      <child link="link_eef2spoon_fixed"/>
      <origin xyz="0.0 0.0 0.2" rpy="-0.6256137488497641 -1.5707917954451251 -2.5159789047421195"/>
   </joint>
   <joint type="fixed" name="link_eef2spoon_fixed_offset">
      <parent link="link_eef2spoon_fixed"/>
      <child link="spoon"/>
      <origin xyz="-0.0 -0.0 -0.0" rpy="0.0 0.0 0.0"/>
   </joint>
   <material name="white">
      <color rgba="1 1 1 1"/>
   </material>
</robot>
